<!-- rosrun gazebo_ros spawn_model -model F-150 -sdf -file /home/bigb/gazebo_f150_ws/src/gazebo_f150/models/F150/model.sdf -->


<?xml version="1.0" ?>




<sdf version="1.5">
  <model name="F150">
    <pose>0 0 0 0 0 0</pose>
    <static>false</static>
    <self_collide>false</self_collide>

    <link name="chassis">
    <pose>-1.953 0 0.84451 0 0 0</pose>
      <inertial>
        <inertia>
          <ixx>904</ixx>
          <ixy>0</ixy>
          <ixz>0</ixz>
          <iyy>5584</iyy>
          <iyz>0</iyz>
          <izz>5900</izz>
        </inertia>
        <mass>2260.0</mass>
      </inertial>
      <collision name="collision_chassis_front">
        <pose>0.935 0 0.15000000000000002 0 0 0</pose>
        <geometry>
          <box>
            <size>3.370 1.80 1.56</size>
          </box>
        </geometry>
      </collision>
      <collision name="collision_chassis_back">
        <pose>-1.770 0 -0.10350000000000004 0 0 0</pose>
        <geometry>
          <box>
            <size>2.035 1.80 1.053</size>
          </box>
        </geometry>
      </collision>
      <visual name="visual_chassis_base">
        <!--
        <geometry>
          <box>
            <size>0.1 0.1 0.1</size>
          </box>
        </geometry>
      -->
        <geometry>
          <mesh>
            <uri>model://F150/meshes/F150.dae</uri>
          </mesh>
        </geometry>
      </visual>
    </link>

    <link name="steering_centerlink_link">
    <pose>-0.340540632326142 0 0.445 0 0 0</pose>
      <inertial>
        <inertia>
          <ixx>0.1</ixx>
          <ixy>0</ixy>
          <ixz>0</ixz>
          <iyy>0.1</iyy>
          <iyz>0</iyz>
          <izz>0.1</izz>
        </inertia>
        <mass>0.1</mass>
      </inertial>
      <collision name="collision">
        <pose>0 0 0 0 0 0</pose>
        <geometry>
            <box>
              <size>0.1 0.1 0.1</size>
            </box>
        </geometry>
      </collision>
      <visual name="visual">
        <pose>0 0 0 1.57079632679 0 0</pose>
        <geometry>
          <cylinder>
            <radius>0.01</radius>
            <length>1.15</length>
          </cylinder>
        </geometry>
      </visual>
    </link>

    <joint name="centerlink2chassis_joint" type="prismatic">
      <parent>chassis</parent>
      <child>steering_centerlink_link</child>
      <pose>0 0 0 0 0 0</pose>
      <axis>
        <xyz>0 1 0</xyz>
        <dynamics>
          <spring_stiffness>10000000</spring_stiffness>
          <damping>35000</damping>
          <friction>10000</friction>
          <spring_reference>0</spring_reference>
        </dynamics>
      </axis>
    </joint>


    

    <link name="front_left_wheel_link">
    <pose>0 0.8665 0.445 0 0 0</pose>
      <inertial>
        <inertia>
          <ixx>2</ixx>
          <ixy>0</ixy>
          <ixz>0</ixz>
          <iyy>3.46</iyy>
          <iyz>0</iyz>
          <izz>2</izz>
        </inertia>
        <mass>35.0</mass>
      </inertial>
      <collision name="collision">
      <pose>0 0 0 1.5707963267948966 0 0</pose>
        <geometry>
          <cylinder>
            <radius>0.445</radius>
            <length>0.297</length>
          </cylinder>
        </geometry>
        <surface>
          <friction>
            <ode>
              <mu>0.7</mu>
              <mu2>0.7</mu2>
            </ode>
          </friction>
        </surface>
      </collision>
      <visual name="visual">
      <pose>0 0 0 0 0 3.141592653589793</pose>
        <geometry>
          <mesh>
            <uri>model://F150/meshes/wheel.dae</uri>
          </mesh>
        </geometry>
      </visual>
      <frame name="left_wheel_frame">
      </frame>
    </link>

    <link name="left_steering_arm_link">
    <pose>-0.170270316163071 0.826089364843796  0.445  0 0 0</pose> <!-- Front wheel position with rotation -->
      <inertial>
        <inertia>
          <ixx>0.1</ixx>
          <ixy>0</ixy>
          <ixz>0</ixz>
          <iyy>0.1</iyy>
          <iyz>0</iyz>
          <izz>0.1</izz>
        </inertia>
        <mass>0.1</mass>
      </inertial>
      <collision name="collision">
        <pose>0 0 0 0 0 0</pose>
        <geometry>
          <cylinder>
            <radius>0.005</radius>
            <length>0.01</length>
          </cylinder>
        </geometry>
      </collision>
      <visual name="visual">
        <pose> 0 0 0 0 1.5707963267948966 0.23302098997801912</pose>
        <geometry>
          <cylinder>
            <radius>0.01</radius>
            <length>0.35</length>
          </cylinder>
        </geometry>
      </visual>
    </link>

    <link name="left_tierod_link">
    <pose>-0.340540632326142 0.6803393648437959 0.445 0 0 0</pose> <!-- Front wheel position with rotation -->
      <inertial>
        <inertia>
          <ixx>0.1</ixx>
          <ixy>0</ixy>
          <ixz>0</ixz>
          <iyy>0.1</iyy>
          <iyz>0</iyz>
          <izz>0.1</izz>
        </inertia>
        <mass>0.1</mass>
      </inertial>
      <collision name="collision">
        <pose>0 0 0 0 0 0</pose>
        <geometry>
          <box>
            <size>0.1 0.1 0.1</size>
          </box>
        </geometry>
      </collision>
      <visual name="visual">
        <pose>0 0 0 1.5707963267948966 0 0</pose>
        <geometry>
          <cylinder>
            <radius>0.01</radius>
            <length>0.21067872968759194</length>
          </cylinder>
        </geometry>
      </visual>
    </link>

    <link name="front_left_suspension_link">
    <pose>0 0.8665 0.595 0 0 0</pose>
      <inertial>
        <inertia>
          <ixx>0.1</ixx>
          <ixy>0</ixy>
          <ixz>0</ixz>
          <iyy>0.1</iyy>
          <iyz>0</iyz>
          <izz>0.1</izz>
        </inertia>
        <mass>0.01</mass>
      </inertial>

      <collision name="collision">
      <pose>0 0 0 0 0 0</pose>
        <geometry>
          <box>
            <size>0.1 0.1 0.1</size>
          </box>
        </geometry>
      </collision>

      <visual name="visual">
      <pose>0 0 0 0 0 0 </pose>
        <geometry>
          <cylinder>
            <radius>0.01</radius>
            <length>0.3</length>
          </cylinder>
        </geometry>
      </visual>
    </link>

    <joint name="left_arm2wheel_joint" type="revolute">
      <parent>left_steering_arm_link</parent>
      <child>front_left_wheel_link</child>
      <pose>0 0 0 0 0 0</pose>
      <axis>
        <xyz>0 1 0</xyz>
      </axis>
    </joint>

    <joint name="left_arm2tierod_joint" type="ball">
      <parent>left_steering_arm_link</parent>
      <child>left_tierod_link</child>
      <pose>0 0.10533936484379597 0 0 0 0</pose>
    </joint>

    <joint name="left_tierod2centerlink_joint" type="ball">
      <parent>steering_centerlink_link</parent>
      <child>left_tierod_link</child>
      <pose>0 -0.10533936484379597 0 0 0 0</pose>
    </joint>

    <joint name="left_wheel2chassis_joint" type="revolute">
      <parent>left_steering_arm_link</parent>
      <child>front_left_suspension_link</child>
      <pose>0 0 0.15 0 0 0</pose>
      <axis>
        <xyz>0 0 1</xyz>
      </axis>
    </joint>

    <joint name="front_left_suspension2chassis_joint" type="prismatic">
      <parent>chassis</parent>
      <child>front_left_suspension_link</child>
      <pose>0 0 0 0 0 0</pose>
      <axis>
        <xyz>0 0 1</xyz>
        <dynamics>
          <spring_stiffness>60000</spring_stiffness>
          <damping>5000</damping>
          <spring_reference>-0.0645</spring_reference>
        </dynamics>
      </axis>
    </joint>

    <link name="rear_left_wheel_link">
    <pose>-3.651 0.8665 0.445 0 0 0</pose>
      <inertial>
        <inertia>
          <ixx>2</ixx>
          <ixy>0</ixy>
          <ixz>0</ixz>
          <iyy>3.46</iyy>
          <iyz>0</iyz>
          <izz>2</izz>
        </inertia>
        <mass>35.0</mass>
      </inertial>

      <collision name="collision">
      <pose>0 0 0 1.5707963267948966 0 0</pose>
        <geometry>
          <cylinder>
            <radius>0.445</radius>
            <length>0.297</length>
          </cylinder>
        </geometry>
        <surface>
          <friction>
            <ode>
              <mu>0.7</mu>
              <mu2>0.7</mu2>
            </ode>
          </friction>
        </surface>
      </collision>

      <visual name="visual">
      <pose>0 0 0 3.141592653589793 0 0 </pose>
        <geometry>
          <mesh>
            <uri>model://F150/meshes/wheel.dae</uri>
          </mesh>
        </geometry>
      </visual>
    </link>

    <link name="rear_left_suspension_link">
    <pose>-3.651 0.8665 0.595 0 0 0</pose>
      <inertial>
        <inertia>
          <ixx>0.1</ixx>
          <ixy>0</ixy>
          <ixz>0</ixz>
          <iyy>0.1</iyy>
          <iyz>0</iyz>
          <izz>0.1</izz>
        </inertia>
        <mass>0.01</mass>
      </inertial>

      <collision name="collision">
      <pose>0 0 0 0 0 0</pose>
        <geometry>
          <box>
            <size>0.1 0.1 0.1</size>
          </box>
        </geometry>
      </collision>

      <visual name="visual">
      <pose>0 0 0 0 0 0 </pose>
        <geometry>
          <cylinder>
            <radius>0.01</radius>
            <length>0.3</length>
          </cylinder>
        </geometry>
      </visual>
    </link>

    <joint name="rear_left_wheel2suspension_joint" type="revolute">
      <parent>rear_left_suspension_link</parent>
      <child>rear_left_wheel_link</child>
      <pose>0 0 0 0 0 0</pose>
      <axis>
        <xyz>0 1 0</xyz>
      </axis>
    </joint>

    <joint name="rear_left_suspension2chassis_joint" type="prismatic">
      <parent>chassis</parent>
      <child>rear_left_suspension_link</child>
      <pose>0 0 0 0 0 0</pose>
      <axis>
        <xyz>0 0 1</xyz>
        <dynamics>
          <spring_stiffness>60000</spring_stiffness>
          <damping>5000</damping>
          <spring_reference>-0.073</spring_reference>
        </dynamics>
      </axis>
    </joint>




    <link name="front_right_wheel_link">
    <pose>0 -0.8665 0.445 0 0 0</pose>
      <inertial>
        <inertia>
          <ixx>2</ixx>
          <ixy>0</ixy>
          <ixz>0</ixz>
          <iyy>3.46</iyy>
          <iyz>0</iyz>
          <izz>2</izz>
        </inertia>
        <mass>35.0</mass>
      </inertial>
      <collision name="collision">
      <pose>0 0 0 1.5707963267948966 0 0</pose>
        <geometry>
          <cylinder>
            <radius>0.445</radius>
            <length>0.297</length>
          </cylinder>
        </geometry>
        <surface>
          <friction>
            <ode>
              <mu>0.7</mu>
              <mu2>0.7</mu2>
            </ode>
          </friction>
        </surface>
      </collision>
      <visual name="visual">
      <pose>0 0 0 0 0 0.0</pose>
        <geometry>
          <mesh>
            <uri>model://F150/meshes/wheel.dae</uri>
          </mesh>
        </geometry>
      </visual>
      <frame name="right_wheel_frame">
      </frame>
    </link>

    <link name="right_steering_arm_link">
    <pose>-0.170270316163071 -0.826089364843796  0.445  0 0 0</pose> <!-- Front wheel position with rotation -->
      <inertial>
        <inertia>
          <ixx>0.1</ixx>
          <ixy>0</ixy>
          <ixz>0</ixz>
          <iyy>0.1</iyy>
          <iyz>0</iyz>
          <izz>0.1</izz>
        </inertia>
        <mass>0.1</mass>
      </inertial>
      <collision name="collision">
        <pose>0 0 0 0 0 0</pose>
        <geometry>
          <cylinder>
            <radius>0.005</radius>
            <length>0.01</length>
          </cylinder>
        </geometry>
      </collision>
      <visual name="visual">
        <pose> 0 0 0 0 1.5707963267948966 -0.23302098997801912</pose>
        <geometry>
          <cylinder>
            <radius>0.01</radius>
            <length>0.35</length>
          </cylinder>
        </geometry>
      </visual>
    </link>

    <link name="right_tierod_link">
    <pose>-0.340540632326142 -0.6803393648437959 0.445 0 0 0</pose> <!-- Front wheel position with rotation -->
      <inertial>
        <inertia>
          <ixx>0.1</ixx>
          <ixy>0</ixy>
          <ixz>0</ixz>
          <iyy>0.1</iyy>
          <iyz>0</iyz>
          <izz>0.1</izz>
        </inertia>
        <mass>0.1</mass>
      </inertial>
      <collision name="collision">
        <pose>0 0 0 0 0 0</pose>
        <geometry>
          <box>
            <size>0.1 0.1 0.1</size>
          </box>
        </geometry>
      </collision>
      <visual name="visual">
        <pose>0 0 0 1.5707963267948966 0 0</pose>
        <geometry>
          <cylinder>
            <radius>0.01</radius>
            <length>0.21067872968759194</length>
          </cylinder>
        </geometry>
      </visual>
    </link>

    <link name="front_right_suspension_link">
    <pose>0 -0.8665 0.595 0 0 0</pose>
      <inertial>
        <inertia>
          <ixx>0.1</ixx>
          <ixy>0</ixy>
          <ixz>0</ixz>
          <iyy>0.1</iyy>
          <iyz>0</iyz>
          <izz>0.1</izz>
        </inertia>
        <mass>0.01</mass>
      </inertial>

      <collision name="collision">
      <pose>0 0 0 0 0 0</pose>
        <geometry>
          <box>
            <size>0.1 0.1 0.1</size>
          </box>
        </geometry>
      </collision>

      <visual name="visual">
      <pose>0 0 0 0 0 0 </pose>
        <geometry>
          <cylinder>
            <radius>0.01</radius>
            <length>0.3</length>
          </cylinder>
        </geometry>
      </visual>
    </link>

    <joint name="right_arm2wheel_joint" type="revolute">
      <parent>right_steering_arm_link</parent>
      <child>front_right_wheel_link</child>
      <pose>0 0 0 0 0 0</pose>
      <axis>
        <xyz>0 1 0</xyz>
      </axis>
    </joint>

    <joint name="right_arm2tierod_joint" type="ball">
      <parent>right_steering_arm_link</parent>
      <child>right_tierod_link</child>
      <pose>0 -0.10533936484379597 0 0 0 0</pose>
    </joint>

    <joint name="right_tierod2centerlink_joint" type="ball">
      <parent>steering_centerlink_link</parent>
      <child>right_tierod_link</child>
      <pose>0 0.10533936484379597 0 0 0 0</pose>
    </joint>

    <joint name="right_wheel2chassis_joint" type="revolute">
      <parent>right_steering_arm_link</parent>
      <child>front_right_suspension_link</child>
      <pose>0 0 0.15 0 0 0</pose>
      <axis>
        <xyz>0 0 1</xyz>
      </axis>
    </joint>

    <joint name="front_right_suspension2chassis_joint" type="prismatic">
      <parent>chassis</parent>
      <child>front_right_suspension_link</child>
      <pose>0 0 0 0 0 0</pose>
      <axis>
        <xyz>0 0 1</xyz>
        <dynamics>
          <spring_stiffness>60000</spring_stiffness>
          <damping>5000</damping>
          <spring_reference>-0.0645</spring_reference>
        </dynamics>
      </axis>
    </joint>

    <link name="rear_right_wheel_link">
    <pose>-3.651 -0.8665 0.445 0 0 0</pose>
      <inertial>
        <inertia>
          <ixx>2</ixx>
          <ixy>0</ixy>
          <ixz>0</ixz>
          <iyy>3.46</iyy>
          <iyz>0</iyz>
          <izz>2</izz>
        </inertia>
        <mass>35.0</mass>
      </inertial>

      <collision name="collision">
      <pose>0 0 0 1.5707963267948966 0 0</pose>
        <geometry>
          <cylinder>
            <radius>0.445</radius>
            <length>0.297</length>
          </cylinder>
        </geometry>
        <surface>
          <friction>
            <ode>
              <mu>0.7</mu>
              <mu2>0.7</mu2>
            </ode>
          </friction>
        </surface>
      </collision>

      <visual name="visual">
      <pose>0 0 0 0.0 0 0 </pose>
        <geometry>
          <mesh>
            <uri>model://F150/meshes/wheel.dae</uri>
          </mesh>
        </geometry>
      </visual>
    </link>

    <link name="rear_right_suspension_link">
    <pose>-3.651 -0.8665 0.595 0 0 0</pose>
      <inertial>
        <inertia>
          <ixx>0.1</ixx>
          <ixy>0</ixy>
          <ixz>0</ixz>
          <iyy>0.1</iyy>
          <iyz>0</iyz>
          <izz>0.1</izz>
        </inertia>
        <mass>0.01</mass>
      </inertial>

      <collision name="collision">
      <pose>0 0 0 0 0 0</pose>
        <geometry>
          <box>
            <size>0.1 0.1 0.1</size>
          </box>
        </geometry>
      </collision>

      <visual name="visual">
      <pose>0 0 0 0 0 0 </pose>
        <geometry>
          <cylinder>
            <radius>0.01</radius>
            <length>0.3</length>
          </cylinder>
        </geometry>
      </visual>
    </link>

    <joint name="rear_right_wheel2suspension_joint" type="revolute">
      <parent>rear_right_suspension_link</parent>
      <child>rear_right_wheel_link</child>
      <pose>0 0 0 0 0 0</pose>
      <axis>
        <xyz>0 1 0</xyz>
      </axis>
    </joint>

    <joint name="rear_right_suspension2chassis_joint" type="prismatic">
      <parent>chassis</parent>
      <child>rear_right_suspension_link</child>
      <pose>0 0 0 0 0 0</pose>
      <axis>
        <xyz>0 0 1</xyz>
        <dynamics>
          <spring_stiffness>60000</spring_stiffness>
          <damping>5000</damping>
          <spring_reference>-0.073</spring_reference>
        </dynamics>
      </axis>
    </joint>






</model>
</sdf>
