<?xml version="1.0" ?>

<%

# Vehicle Specs
chassis_mass          = 2260.0 # kg
wheelbase             = 3.651 # m
track_width           = 1.733 # m
wheel_radius          = 0.445 # m
wheel_width           = 0.297 # m
chassis_center_x      = 1.953 # m from front wheels
chassis_center_z      = 0.84451 # m
cg_x                  = 1.42 # m
cg_z                  = 0.7 # m

# Wheel limits
turn_radius_curb2curb = 13.95 #m

wheel_limit           = Math::asin(wheelbase/(turn_radius_curb2curb - (0.5 * track_width))) # rad

# Suspension parameters
front_weight_loading = cg_x / wheelbase;

damping = Math::sqrt(2)/2
desired_freq    = 2 * Math::PI # Desired comfort factor of 1 hz

freq = desired_freq / Math::sqrt(1 - (damping * damping))
#TODO setup different freq for rear and front suspension to control pitch dynamic


weight_on_front_wheels            = chassis_mass * (1 - front_weight_loading)
front_suspension_stiffness        = (freq * freq)* 0.5 * weight_on_front_wheels
front_suspension_damping          = 2 * damping * Math::sqrt(front_suspension_stiffness * 0.5 * weight_on_front_wheels)
front_suspension_spring_reference = - 0.5 * weight_on_front_wheels * 9.81 / front_suspension_stiffness

weight_on_rear_wheels             = chassis_mass * front_weight_loading
rear_suspension_stiffness         = (freq * freq)* 0.5 * weight_on_rear_wheels
rear_suspension_damping           = 2 * damping * Math::sqrt(rear_suspension_stiffness * 0.5 * weight_on_rear_wheels)
rear_suspension_spring_reference  = - 0.5 * weight_on_rear_wheels * 9.81 / rear_suspension_stiffness

wheel_static_friction                    = 10;

# Steering system paramters
ackermann_angle       = Math::atan2(track_width/2,wheelbase)
centerline_length     = 1.15
steering_arm_length   = 0.6 #0.35

steering_arm_x        = -Math::cos(ackermann_angle)*steering_arm_length
steering_arm_y        = Math::sin(ackermann_angle)*steering_arm_length

tierod_length         = (track_width - 2*steering_arm_y - centerline_length)/2

front_wheel_locations = {
  "left"  => {:side => 1, :wheel_vis => 1},
  "right" => {:side => -1, :wheel_vis => 0},
}

%>


<sdf version="1.5">
  <model name="F150">
    <pose>0 0 0 0 0 0</pose>
    <static>false</static>
    <self_collide>false</self_collide>

    <link name="chassis">
    <pose><%= -chassis_center_x %> 0 <%= chassis_center_z %> 0 0 0</pose>
      <inertial>
        <pose><%= chassis_center_x-cg_x %> 0 <%= cg_z-chassis_center_z %> 0 0 0</pose>
        <inertia>
          <ixx>904</ixx>
          <ixy>0</ixy>
          <ixz>0</ixz>
          <iyy>5584</iyy>
          <iyz>0</iyz>
          <izz>5900</izz>
        </inertia>
        <mass><%= chassis_mass %></mass>
      </inertial>
      <collision name="collision_chassis_front">
        <pose>0.935 0 <%= 0.99451 - chassis_center_z %> 0 0 0</pose>
        <geometry>
          <box>
            <size>3.370 1.80 1.56</size>
          </box>
        </geometry>
      </collision>
      <collision name="collision_chassis_back">
        <pose>-1.770 0 <%= 0.74101 - chassis_center_z %> 0 0 0</pose>
        <geometry>
          <box>
            <size>2.035 1.80 1.053</size>
          </box>
        </geometry>
      </collision>
      <visual name="visual_chassis_base">
        <!--
        <geometry>
          <box>
            <size>0.1 0.1 0.1</size>
          </box>
        </geometry>
      -->
        <geometry>
          <mesh>
            <uri>model://f150_ackermann/meshes/F150.dae</uri>
          </mesh>
        </geometry>
      </visual>
    </link>

    <link name="steering_centerlink_link">
    <pose><%= steering_arm_x %> 0 <%= wheel_radius + 0.15%> 0 0 0</pose>
      <inertial>
        <inertia>
          <ixx>0.1</ixx>
          <ixy>0</ixy>
          <ixz>0</ixz>
          <iyy>0.1</iyy>
          <iyz>0</iyz>
          <izz>0.1</izz>
        </inertia>
        <mass>0.1</mass>
      </inertial>
      <collision name="collision">
        <pose>0 0 0 0 0 0</pose>
        <geometry>
            <box>
              <size>0.1 0.1 0.1</size>
            </box>
        </geometry>
      </collision>
      <visual name="visual">
        <pose>0 0 0 1.57079632679 0 0</pose>
        <geometry>
          <cylinder>
            <radius>0.01</radius>
            <length><%= centerline_length %></length>
          </cylinder>
        </geometry>
      </visual>
    </link>

    <joint name="centerlink2chassis_joint" type="prismatic">
      <parent>chassis</parent>
      <child>steering_centerlink_link</child>
      <pose>0 0 0 0 0 0</pose>
      <axis>
        <xyz>0 1 0</xyz>
        <dynamics>
          <spring_stiffness>0</spring_stiffness>
          <damping>0</damping>
          <friction>10</friction>
          <spring_reference>0</spring_reference>
        </dynamics>
      </axis>
    </joint>


    <%
      front_wheel_locations.keys.each do |k|
        side = front_wheel_locations[k][:side]
        wheel_vis = front_wheel_locations[k][:wheel_vis]
    %>

    <%= "<link name=" + '"front_' + k +  '_wheel_link">' %>
    <pose>0 <%= side * track_width/2 %> <%= wheel_radius %> 0 0 0</pose>
      <inertial>
        <inertia>
          <ixx>2</ixx>
          <ixy>0</ixy>
          <ixz>0</ixz>
          <iyy>3.46</iyy>
          <iyz>0</iyz>
          <izz>2</izz>
        </inertia>
        <mass>35.0</mass>
      </inertial>
      <collision name="collision">
      <pose>0 0 0 <%= Math::PI/2 %> 0 0</pose>
        <geometry>
          <cylinder>
            <radius><%= wheel_radius %></radius>
            <length><%= wheel_width %></length>
          </cylinder>
        </geometry>
        <surface>
          <friction>
            <ode>
              <mu>0.7</mu>
              <mu2>0.7</mu2>
            </ode>
          </friction>
        </surface>
      </collision>
      <visual name="visual">
      <pose>0 0 0 0 0 <%= wheel_vis * Math::PI %></pose>
        <geometry>
          <mesh>
            <uri>model://f150_ackermann/meshes/wheel.dae</uri>
          </mesh>
        </geometry>
      </visual>
      <frame <%= 'name="' + k +'_wheel_frame"' %>>
      </frame>
    </link>

    <%= "<link name=" + '"' + k + '_steering_arm_link">' %>
    <pose>0 <%= side * (track_width/2) %>  <%= wheel_radius + 0.15 %>  0 0 0</pose> <!-- Front wheel position with rotation -->
      <inertial>
        <inertia>
          <ixx>0.1</ixx>
          <ixy>0</ixy>
          <ixz>0</ixz>
          <iyy>0.1</iyy>
          <iyz>0</iyz>
          <izz>0.1</izz>
        </inertia>
        <mass>0.1</mass>
      </inertial>
      <collision name="collision">
        <pose>0 0 0 0 0 0</pose>
        <geometry>
          <cylinder>
            <radius>0.005</radius>
            <length>0.01</length>
          </cylinder>
        </geometry>
      </collision>
      <visual name="visual">
        <pose> <%= steering_arm_x/2 %> <%= side * -steering_arm_y/2 %> 0 0 <%= Math::PI/2 %> <%= side * ackermann_angle %></pose>
        <geometry>
          <cylinder>
            <radius>0.01</radius>
            <length><%= steering_arm_length %></length>
          </cylinder>
        </geometry>
      </visual>
    </link>

    <%= "<link name=" + '"' + k + '_tierod_link">' %>
    <pose><%= steering_arm_x %> <%= side * (track_width/2 - steering_arm_y - tierod_length/2) %> <%= wheel_radius + 0.15 %> 0 0 0</pose> <!-- Front wheel position with rotation -->
      <inertial>
        <inertia>
          <ixx>0.1</ixx>
          <ixy>0</ixy>
          <ixz>0</ixz>
          <iyy>0.1</iyy>
          <iyz>0</iyz>
          <izz>0.1</izz>
        </inertia>
        <mass>0.1</mass>
      </inertial>
      <collision name="collision">
        <pose>0 0 0 0 0 0</pose>
        <geometry>
          <box>
            <size>0.1 0.1 0.1</size>
          </box>
        </geometry>
      </collision>
      <visual name="visual">
        <pose>0 0 0 <%= Math::PI/2 %> 0 0</pose>
        <geometry>
          <cylinder>
            <radius>0.01</radius>
            <length><%= tierod_length %></length>
          </cylinder>
        </geometry>
      </visual>
    </link>

    <%= "<link name=" + '"front_' + k + '_suspension_link">' %>
    <pose>0 <%= side * track_width/2 %> <%= wheel_radius + (0.3/4) %> 0 0 0</pose>
      <inertial>
        <inertia>
          <ixx>0.1</ixx>
          <ixy>0</ixy>
          <ixz>0</ixz>
          <iyy>0.1</iyy>
          <iyz>0</iyz>
          <izz>0.1</izz>
        </inertia>
        <mass>0.01</mass>
      </inertial>

      <collision name="collision">
      <pose>0 0 0 0 0 0</pose>
        <geometry>
          <box>
            <size>0.1 0.1 0.1</size>
          </box>
        </geometry>
      </collision>

      <visual name="visual">
      <pose>0 0 0 0 0 0 </pose>
        <geometry>
          <cylinder>
            <radius>0.01</radius>
            <length><%= 0.3/2 %></length>
          </cylinder>
        </geometry>
      </visual>
    </link>

    <%= "<joint name=" + '"' + k + '_suspension2wheel_joint" type="revolute">' %>
      <parent><%= 'front_' + k + '_suspension_link' %></parent>
      <child><%= 'front_' + k + '_wheel_link' %></child>
      <pose>0 0 0 0 0 0</pose>
      <axis>
        <xyz>0 1 0</xyz>
        <dynamics>
          <friction><%= wheel_static_friction %></friction>
        </dynamics>
      </axis>
    </joint>

    <%= "<joint name=" + '"' + k + '_arm2tierod_joint" type="revolute">' %>
      <parent><%= k + '_steering_arm_link' %></parent>
      <child><%= k + '_tierod_link'%></child>
      <pose>0 <%= side * tierod_length/2 %> 0 0 0 0</pose>
      <axis>
        <xyz>0 0 1</xyz>
      </axis>
    </joint>

    <%= "<joint name=" + '"' + k + '_tierod2centerlink_joint" type="revolute">' %>
      <parent>steering_centerlink_link</parent>
      <child><%= k + '_tierod_link'%></child>
      <pose>0 <%= -side * tierod_length/2 %> 0 0 0 0</pose>
      <axis>
        <xyz>0 0 1</xyz>
      </axis>
    </joint>

    <%= "<joint name=" + '"' + k + '_chassis2arm_joint" type="revolute">' %>
      <parent>chassis</parent>
      <child><%= k + '_steering_arm_link' %></child>
      <pose>0 0 0 0 0 0</pose>
      <axis>
        <xyz>0 0 1</xyz>
        <limit>
          <lower><%= -wheel_limit %></lower>
          <upper><%= wheel_limit %></upper>
        </limit>
      </axis>
    </joint>

    <%= "<joint name=" + '"front_' + k + '_arm2suspension_joint" type="prismatic">' %>
      <parent><%= k + '_steering_arm_link' %></parent>
      <child><%= 'front_' + k + '_suspension_link' %></child>
      <pose>0 0 0 0 0 0</pose>
      <axis>
        <xyz>0 0 1</xyz>
        <dynamics>
          <spring_stiffness><%= front_suspension_stiffness %></spring_stiffness>
          <damping><%= front_suspension_damping %></damping>
          <spring_reference><%= front_suspension_spring_reference %></spring_reference>
        </dynamics>
      </axis>
    </joint>

    <%= "<link name=" + '"rear_' + k + '_wheel_link">' %>
    <pose><%= -wheelbase %> <%= side * track_width/2 %> <%= wheel_radius %> 0 0 0</pose>
      <inertial>
        <inertia>
          <ixx>2</ixx>
          <ixy>0</ixy>
          <ixz>0</ixz>
          <iyy>3.46</iyy>
          <iyz>0</iyz>
          <izz>2</izz>
        </inertia>
        <mass>35.0</mass>
      </inertial>

      <collision name="collision">
      <pose>0 0 0 <%= Math::PI/2 %> 0 0</pose>
        <geometry>
          <cylinder>
            <radius><%= wheel_radius %></radius>
            <length><%= wheel_width %></length>
          </cylinder>
        </geometry>
        <surface>
          <friction>
            <ode>
              <mu>0.7</mu>
              <mu2>0.7</mu2>
            </ode>
          </friction>
        </surface>
      </collision>

      <visual name="visual">
      <pose>0 0 0 <%= wheel_vis * Math::PI %> 0 0 </pose>
        <geometry>
          <mesh>
            <uri>model://f150_ackermann/meshes/wheel.dae</uri>
          </mesh>
        </geometry>
      </visual>
    </link>

    <%= "<link name=" + '"rear_' + k + '_suspension_link">' %>
    <pose><%= -wheelbase %> <%= side * track_width/2 %> <%= wheel_radius + (0.3/2) %> 0 0 0</pose>
      <inertial>
        <inertia>
          <ixx>0.1</ixx>
          <ixy>0</ixy>
          <ixz>0</ixz>
          <iyy>0.1</iyy>
          <iyz>0</iyz>
          <izz>0.1</izz>
        </inertia>
        <mass>0.01</mass>
      </inertial>

      <collision name="collision">
      <pose>0 0 0 0 0 0</pose>
        <geometry>
          <box>
            <size>0.1 0.1 0.1</size>
          </box>
        </geometry>
      </collision>

      <visual name="visual">
      <pose>0 0 0 0 0 0 </pose>
        <geometry>
          <cylinder>
            <radius>0.01</radius>
            <length>0.3</length>
          </cylinder>
        </geometry>
      </visual>
    </link>

    <%= "<joint name=" + '"rear_' + k + '_wheel2suspension_joint" type="revolute">' %>
      <parent><%= 'rear_' + k + '_suspension_link' %></parent>
      <child><%= 'rear_' + k + '_wheel_link' %></child>
      <pose>0 0 0 0 0 0</pose>
      <axis>
        <xyz>0 1 0</xyz>
        <dynamics>
          <friction><%= wheel_static_friction %></friction>
        </dynamics>
      </axis>
    </joint>

    <%= "<joint name=" + '"rear_' + k + '_suspension2chassis_joint" type="prismatic">' %>
      <parent>chassis</parent>
      <child><%= 'rear_' + k + '_suspension_link' %></child>
      <pose>0 0 0 0 0 0</pose>
      <axis>
        <xyz>0 0 1</xyz>
        <dynamics>
          <spring_stiffness><%= rear_suspension_stiffness %></spring_stiffness>
          <damping><%= rear_suspension_damping %></damping>
          <spring_reference><%= rear_suspension_spring_reference %></spring_reference>
        </dynamics>
      </axis>
    </joint>


<% end %>


<plugin name="motion_controller" filename="libmotion_controller.so">
<center_link_joint>centerlink2chassis_joint</center_link_joint>
<right_front_wheels_joint>right_suspension2wheel_joint</right_front_wheels_joint>
<left_front_wheels_joint>left_suspension2wheel_joint</left_front_wheels_joint>
</plugin>




</model>
</sdf>
